Workbook

Sheet Start here
A1: The 6 Pass · partner pipeline
A2: 441 places to approach, researched October 2026 from public sources. Counts below update by themselves.
A4: How to use it
A5: 1. Work one neighbourhood at a time. Wave 1 is the six launch neighbourhoods; start with Ossington.
A6: 2. Before walking in, check the place is still open (Open? column). Some rows note weak online evidence.
A7: 3. Every row you touch gets a Status, a Next step and a Next step date. Overdue dates turn red.
A8: 4. Write their slow nights and offer idea as you hear them. That becomes their offer in the app.
A9: 5. Be picky: we need 50 Founding Partners, not 300. A 'Not now' with a reason is a good outcome.
A10: Contacts are blank on purpose: ask for the owner or general manager in person, then fill them in.
A13: By status
A14: Target | B14: =COUNTIF(Pipeline!N:N,"Target")
A15: Contacted | B15: =COUNTIF(Pipeline!N:N,"Contacted")
A16: Meeting booked | B16: =COUNTIF(Pipeline!N:N,"Meeting booked")
A17: Met | B17: =COUNTIF(Pipeline!N:N,"Met")
A18: LOI signed | B18: =COUNTIF(Pipeline!N:N,"LOI signed")
A19: Agreement signed | B19: =COUNTIF(Pipeline!N:N,"Agreement signed")
A20: Not now | B20: =COUNTIF(Pipeline!N:N,"Not now")
A21: Goal for the first week: 10 conversations, 5 demos, 2 letters of intent.
A23: Neighbourhood | B23: Places | C23: Contacted+ | D23: Met | E23: LOI signed | F23: Signed
A24: Ossington (wave 1) | B24: =COUNTIF(Pipeline!D:D,"Ossington") | C24: =COUNTIFS(Pipeline!D:D,"Ossington",Pipeline!N:N,"<>Target",Pipeline!N:N,"<>") | D24: =COUNTIFS(Pipeline!D:D,"Ossington",Pipeline!N:N,"Met") | E24: =COUNTIFS(Pipeline!D:D,"Ossington",Pipeline!N:N,"LOI signed") | F24: =COUNTIFS(Pipeline!D:D,"Ossington",Pipeline!N:N,"Agreement signed")
A25: Queen West (wave 1) | B25: =COUNTIF(Pipeline!D:D,"Queen West") | C25: =COUNTIFS(Pipeline!D:D,"Queen West",Pipeline!N:N,"<>Target",Pipeline!N:N,"<>") | D25: =COUNTIFS(Pipeline!D:D,"Queen West",Pipeline!N:N,"Met") | E25: =COUNTIFS(Pipeline!D:D,"Queen West",Pipeline!N:N,"LOI signed") | F25: =COUNTIFS(Pipeline!D:D,"Queen West",Pipeline!N:N,"Agreement signed")
A26: King West (wave 1) | B26: =COUNTIF(Pipeline!D:D,"King West") | C26: =COUNTIFS(Pipeline!D:D,"King West",Pipeline!N:N,"<>Target",Pipeline!N:N,"<>") | D26: =COUNTIFS(Pipeline!D:D,"King West",Pipeline!N:N,"Met") | E26: =COUNTIFS(Pipeline!D:D,"King West",Pipeline!N:N,"LOI signed") | F26: =COUNTIFS(Pipeline!D:D,"King West",Pipeline!N:N,"Agreement signed")
A27: Financial District (wave 1) | B27: =COUNTIF(Pipeline!D:D,"Financial District") | C27: =COUNTIFS(Pipeline!D:D,"Financial District",Pipeline!N:N,"<>Target",Pipeline!N:N,"<>") | D27: =COUNTIFS(Pipeline!D:D,"Financial District",Pipeline!N:N,"Met") | E27: =COUNTIFS(Pipeline!D:D,"Financial District",Pipeline!N:N,"LOI signed") | F27: =COUNTIFS(Pipeline!D:D,"Financial District",Pipeline!N:N,"Agreement signed")
A28: Yorkville (wave 1) | B28: =COUNTIF(Pipeline!D:D,"Yorkville") | C28: =COUNTIFS(Pipeline!D:D,"Yorkville",Pipeline!N:N,"<>Target",Pipeline!N:N,"<>") | D28: =COUNTIFS(Pipeline!D:D,"Yorkville",Pipeline!N:N,"Met") | E28: =COUNTIFS(Pipeline!D:D,"Yorkville",Pipeline!N:N,"LOI signed") | F28: =COUNTIFS(Pipeline!D:D,"Yorkville",Pipeline!N:N,"Agreement signed")
A29: Leslieville (wave 1) | B29: =COUNTIF(Pipeline!D:D,"Leslieville") | C29: =COUNTIFS(Pipeline!D:D,"Leslieville",Pipeline!N:N,"<>Target",Pipeline!N:N,"<>") | D29: =COUNTIFS(Pipeline!D:D,"Leslieville",Pipeline!N:N,"Met") | E29: =COUNTIFS(Pipeline!D:D,"Leslieville",Pipeline!N:N,"LOI signed") | F29: =COUNTIFS(Pipeline!D:D,"Leslieville",Pipeline!N:N,"Agreement signed")
A30: Little Italy | B30: =COUNTIF(Pipeline!D:D,"Little Italy") | C30: =COUNTIFS(Pipeline!D:D,"Little Italy",Pipeline!N:N,"<>Target",Pipeline!N:N,"<>") | D30: =COUNTIFS(Pipeline!D:D,"Little Italy",Pipeline!N:N,"Met") | E30: =COUNTIFS(Pipeline!D:D,"Little Italy",Pipeline!N:N,"LOI signed") | F30: =COUNTIFS(Pipeline!D:D,"Little Italy",Pipeline!N:N,"Agreement signed")
A31: Kensington and Chinatown | B31: =COUNTIF(Pipeline!D:D,"Kensington and Chinatown") | C31: =COUNTIFS(Pipeline!D:D,"Kensington and Chinatown",Pipeline!N:N,"<>Target",Pipeline!N:N,"<>") | D31: =COUNTIFS(Pipeline!D:D,"Kensington and Chinatown",Pipeline!N:N,"Met") | E31: =COUNTIFS(Pipeline!D:D,"Kensington and Chinatown",Pipeline!N:N,"LOI signed") | F31: =COUNTIFS(Pipeline!D:D,"Kensington and Chinatown",Pipeline!N:N,"Agreement signed")
A32: The Annex | B32: =COUNTIF(Pipeline!D:D,"The Annex") | C32: =COUNTIFS(Pipeline!D:D,"The Annex",Pipeline!N:N,"<>Target",Pipeline!N:N,"<>") | D32: =COUNTIFS(Pipeline!D:D,"The Annex",Pipeline!N:N,"Met") | E32: =COUNTIFS(Pipeline!D:D,"The Annex",Pipeline!N:N,"LOI signed") | F32: =COUNTIFS(Pipeline!D:D,"The Annex",Pipeline!N:N,"Agreement signed")
A33: Roncesvalles | B33: =COUNTIF(Pipeline!D:D,"Roncesvalles") | C33: =COUNTIFS(Pipeline!D:D,"Roncesvalles",Pipeline!N:N,"<>Target",Pipeline!N:N,"<>") | D33: =COUNTIFS(Pipeline!D:D,"Roncesvalles",Pipeline!N:N,"Met") | E33: =COUNTIFS(Pipeline!D:D,"Roncesvalles",Pipeline!N:N,"LOI signed") | F33: =COUNTIFS(Pipeline!D:D,"Roncesvalles",Pipeline!N:N,"Agreement signed")
A34: Danforth | B34: =COUNTIF(Pipeline!D:D,"Danforth") | C34: =COUNTIFS(Pipeline!D:D,"Danforth",Pipeline!N:N,"<>Target",Pipeline!N:N,"<>") | D34: =COUNTIFS(Pipeline!D:D,"Danforth",Pipeline!N:N,"Met") | E34: =COUNTIFS(Pipeline!D:D,"Danforth",Pipeline!N:N,"LOI signed") | F34: =COUNTIFS(Pipeline!D:D,"Danforth",Pipeline!N:N,"Agreement signed")
A35: Liberty Village | B35: =COUNTIF(Pipeline!D:D,"Liberty Village") | C35: =COUNTIFS(Pipeline!D:D,"Liberty Village",Pipeline!N:N,"<>Target",Pipeline!N:N,"<>") | D35: =COUNTIFS(Pipeline!D:D,"Liberty Village",Pipeline!N:N,"Met") | E35: =COUNTIFS(Pipeline!D:D,"Liberty Village",Pipeline!N:N,"LOI signed") | F35: =COUNTIFS(Pipeline!D:D,"Liberty Village",Pipeline!N:N,"Agreement signed")
A36: Little Portugal | B36: =COUNTIF(Pipeline!D:D,"Little Portugal") | C36: =COUNTIFS(Pipeline!D:D,"Little Portugal",Pipeline!N:N,"<>Target",Pipeline!N:N,"<>") | D36: =COUNTIFS(Pipeline!D:D,"Little Portugal",Pipeline!N:N,"Met") | E36: =COUNTIFS(Pipeline!D:D,"Little Portugal",Pipeline!N:N,"LOI signed") | F36: =COUNTIFS(Pipeline!D:D,"Little Portugal",Pipeline!N:N,"Agreement signed")
A37: Parkdale | B37: =COUNTIF(Pipeline!D:D,"Parkdale") | C37: =COUNTIFS(Pipeline!D:D,"Parkdale",Pipeline!N:N,"<>Target",Pipeline!N:N,"<>") | D37: =COUNTIFS(Pipeline!D:D,"Parkdale",Pipeline!N:N,"Met") | E37: =COUNTIFS(Pipeline!D:D,"Parkdale",Pipeline!N:N,"LOI signed") | F37: =COUNTIFS(Pipeline!D:D,"Parkdale",Pipeline!N:N,"Agreement signed")
A38: The Junction | B38: =COUNTIF(Pipeline!D:D,"The Junction") | C38: =COUNTIFS(Pipeline!D:D,"The Junction",Pipeline!N:N,"<>Target",Pipeline!N:N,"<>") | D38: =COUNTIFS(Pipeline!D:D,"The Junction",Pipeline!N:N,"Met") | E38: =COUNTIFS(Pipeline!D:D,"The Junction",Pipeline!N:N,"LOI signed") | F38: =COUNTIFS(Pipeline!D:D,"The Junction",Pipeline!N:N,"Agreement signed")
A39: St. Clair West | B39: =COUNTIF(Pipeline!D:D,"St. Clair West") | C39: =COUNTIFS(Pipeline!D:D,"St. Clair West",Pipeline!N:N,"<>Target",Pipeline!N:N,"<>") | D39: =COUNTIFS(Pipeline!D:D,"St. Clair West",Pipeline!N:N,"Met") | E39: =COUNTIFS(Pipeline!D:D,"St. Clair West",Pipeline!N:N,"LOI signed") | F39: =COUNTIFS(Pipeline!D:D,"St. Clair West",Pipeline!N:N,"Agreement signed")
A40: Distillery and Corktown | B40: =COUNTIF(Pipeline!D:D,"Distillery and Corktown") | C40: =COUNTIFS(Pipeline!D:D,"Distillery and Corktown",Pipeline!N:N,"<>Target",Pipeline!N:N,"<>") | D40: =COUNTIFS(Pipeline!D:D,"Distillery and Corktown",Pipeline!N:N,"Met") | E40: =COUNTIFS(Pipeline!D:D,"Distillery and Corktown",Pipeline!N:N,"LOI signed") | F40: =COUNTIFS(Pipeline!D:D,"Distillery and Corktown",Pipeline!N:N,"Agreement signed")
A41: Summerhill and Rosedale | B41: =COUNTIF(Pipeline!D:D,"Summerhill and Rosedale") | C41: =COUNTIFS(Pipeline!D:D,"Summerhill and Rosedale",Pipeline!N:N,"<>Target",Pipeline!N:N,"<>") | D41: =COUNTIFS(Pipeline!D:D,"Summerhill and Rosedale",Pipeline!N:N,"Met") | E41: =COUNTIFS(Pipeline!D:D,"Summerhill and Rosedale",Pipeline!N:N,"LOI signed") | F41: =COUNTIFS(Pipeline!D:D,"Summerhill and Rosedale",Pipeline!N:N,"Agreement signed")
A42: Midtown | B42: =COUNTIF(Pipeline!D:D,"Midtown") | C42: =COUNTIFS(Pipeline!D:D,"Midtown",Pipeline!N:N,"<>Target",Pipeline!N:N,"<>") | D42: =COUNTIFS(Pipeline!D:D,"Midtown",Pipeline!N:N,"Met") | E42: =COUNTIFS(Pipeline!D:D,"Midtown",Pipeline!N:N,"LOI signed") | F42: =COUNTIFS(Pipeline!D:D,"Midtown",Pipeline!N:N,"Agreement signed")
A43: Leaside | B43: =COUNTIF(Pipeline!D:D,"Leaside") | C43: =COUNTIFS(Pipeline!D:D,"Leaside",Pipeline!N:N,"<>Target",Pipeline!N:N,"<>") | D43: =COUNTIFS(Pipeline!D:D,"Leaside",Pipeline!N:N,"Met") | E43: =COUNTIFS(Pipeline!D:D,"Leaside",Pipeline!N:N,"LOI signed") | F43: =COUNTIFS(Pipeline!D:D,"Leaside",Pipeline!N:N,"Agreement signed")
A44: Riverdale | B44: =COUNTIF(Pipeline!D:D,"Riverdale") | C44: =COUNTIFS(Pipeline!D:D,"Riverdale",Pipeline!N:N,"<>Target",Pipeline!N:N,"<>") | D44: =COUNTIFS(Pipeline!D:D,"Riverdale",Pipeline!N:N,"Met") | E44: =COUNTIFS(Pipeline!D:D,"Riverdale",Pipeline!N:N,"LOI signed") | F44: =COUNTIFS(Pipeline!D:D,"Riverdale",Pipeline!N:N,"Agreement signed")
...

Sheet Pipeline
A1: # | B1: Wave | C1: Place | D1: Neighbourhood | E1: Category | F1: Cuisine or type | G1: Address | H1: Website | I1: Instagram | J1: Phone | K1: Price | L1: Why it fits | M1: Open? | N1: Status | O1: Contact name | P1: Role | Q1: Contact email or phone | R1: How we know them | S1: Last contact | T1: Next step | U1: Next step date | V1: Slow nights | W1: Offer idea | X1: Notes | Y1: Source
A2: 1 | B2: 1 | C2: Actinolite | D2: Ossington | E2: Restaurant | F2: Contemporary Canadian tasting menu | G2: 971 Ossington Ave | H2: https://www.actinoliterestaurant.com | I2: @actinoliterestaurant | J2: 416-962-8943 | K2: $$$$ | L2: Seasonal tasting-menu room north of the strip, suits an upgrade-style offer. | M2: Not checked | N2: Target | Y2: https://guide.michelin.com/ca/en/ontario/toronto/restaurant/actinolite
A3: 2 | B3: 1 | C3: Antler | D3: Ossington | E3: Restaurant | F3: Wild and foraged Canadian | G3: 1454 Dundas St W | H3: https://www.antlerkitchenbar.com | I3: @antlerkitchenbar | J3: 647-345-8300 | K3: $$$ | L3: Game and foraged menu, a bit further west on Dundas. | M3: Not checked | N3: Target | Y3: https://guide.michelin.com/ca/en/ontario/toronto/restaurant/antler
A4: 3 | B4: 1 | C4: Azhar Kitchen & Bar | D4: Ossington | E4: Restaurant | F4: Middle Eastern | G4: 96 Ossington Ave | H4: https://azhartoronto.com | I4: @azhartoronto | L4: Wood-fired Middle Eastern plates, easy for two. | M4: Not checked | N4: Target | X4: Check it's open before visiting: weak online evidence. | Y4: https://azhartoronto.com
A5: 4 | B5: 1 | C5: Côte de Boeuf | D5: Ossington | E5: Restaurant | F5: French bistro and butcher | G5: 130 Ossington Ave | H5: https://cotedeboeuf.ca | I5: @cotedeboeufossington | L5: Walk-in steak frites bistro, a well-known name on the strip. | M5: Not checked | N5: Target | X5: Check it's open before visiting: weak online evidence. | Y5: https://cotedeboeuf.ca
A6: 5 | B6: 1 | C6: Enoteca Sociale | D6: Ossington | E6: Restaurant | F6: Roman Italian | G6: 1288 Dundas St W | H6: https://sociale.ca | J6: 416-534-1200 | K6: $$ | L6: Bib Gourmand pasta spot on Dundas West. | M6: Not checked | N6: Target | Y6: https://guide.michelin.com/ca/en/ontario/toronto/restaurant/enoteca-sociale
A7: 6 | B7: 1 | C7: Fallen Feather | D7: Ossington | E7: Restaurant | F7: Modern Asian with French technique | I7: @fallenfeather217 | L7: Stylish Asian-French dinner room on the strip. | M7: Not checked | N7: Target | Y7: https://streetsoftoronto.com/food/5-spots-on-ossington-every-foodie-needs-to-try/
A8: 7 | B8: 1 | C8: Fat Choi | D8: Ossington | E8: Restaurant | F8: Plant-based Malaysian and Nyonya | G8: 94 Ossington Ave | H8: https://www.fatchoito.com | J8: 416-901-7667 | L8: Vegan tasting menus, a different option for the list. | M8: Not checked | N8: Target | X8: Check it's open before visiting: weak online evidence. | Y8: https://www.fatchoito.com
A9: 8 | B9: 1 | C9: Favorites Thai | D9: Ossington | E9: Restaurant | F9: Thai, charcoal BBQ | G9: 141 Ossington Ave | H9: https://www.myfavethai.com | I9: @myfavethai | J9: 647-867-3283 | K9: $$ | L9: Bib Gourmand Thai BBQ, a strong value story for members. | M9: Not checked | N9: Target | Y9: https://guide.michelin.com/ca/en/ontario/toronto/restaurant/favorites-thai
A10: 9 | B10: 1 | C10: Gia | D10: Ossington | E10: Restaurant | F10: Plant-forward Italian | G10: 1214 Dundas St W | H10: https://giarestaurant.ca | I10: @giatoronto | J10: 416-535-8888 | K10: $$$ | L10: Plant-forward Italian with Michelin recognition. | M10: Not checked | N10: Target | Y10: https://guide.michelin.com/ca/en/ontario/toronto/restaurant/gia
A11: 10 | B11: 1 | C11: Imanishi Japanese Kitchen | D11: Ossington | E11: Restaurant | F11: Japanese home-style | G11: 1330 Dundas St W | H11: https://www.imanishi.ca | I11: @imanishijapanesekitchen | J11: 416-706-4225 | L11: Tokyo home-style plates in a calm room on Dundas West. | M11: Not checked | N11: Target | Y11: https://streetsoftoronto.com/food/5-restaurants-on-dundas-west-that-every-foodie-needs-to-try/
A12: 11 | B12: 1 | C12: La Banane | D12: Ossington | E12: Restaurant | F12: French, raw bar | G12: 227 Ossington Ave | H12: https://www.labanane.ca | I12: @labananeresto | J12: 416-551-6263 | K12: $$$$ | L12: Michelin-listed French room with a raw bar, good for a special night out. | M12: Not checked | N12: Target | Y12: https://guide.michelin.com/ca/en/ontario/toronto/restaurant/la-banane
A13: 12 | B13: 1 | C13: Linny's | D13: Ossington | E13: Restaurant | F13: Steakhouse, deli | G13: 176 Ossington Ave | H13: https://linnysrestaurant.com | I13: @linnysrestaurant | J13: 647-390-1836 | K13: $$$$ | L13: Premium deli-steakhouse that would be a headline name on the list. | M13: Not checked | N13: Target | Y13: https://guide.michelin.com/ca/en/ontario/toronto/restaurant/linny-s
A14: 13 | B14: 1 | C14: Mamakas Taverna | D14: Ossington | E14: Restaurant | F14: Greek | G14: 80 Ossington Ave | H14: https://mamakas.ca/locations/mamakas-ossington/ | I14: @mamakastaverna | J14: 416-519-5996 | L14: Polished Greek taverna built around sharing plates. | M14: Not checked | N14: Target | Y14: https://mamakas.ca/locations/mamakas-ossington/
A15: 14 | B15: 1 | C15: MSSM Ossington | D15: Ossington | E15: Restaurant | F15: Japanese omakase | G15: 1221 Dundas St W | H15: https://mssmossington.ca | I15: @mssmossington | L15: Edomae omakase counter, a premium sushi option. | M15: Not checked | N15: Target | X15: Check it's open before visiting: weak online evidence. | Y15: https://mssmossington.ca
A16: 15 | B16: 1 | C16: OddSeoul | D16: Ossington | E16: Restaurant | F16: Korean small plates | G16: 90 Ossington Ave | H16: https://oddseoul.ca | I16: @90oddseoul | L16: Late-night Korean small plates, good for a casual date. | M16: Not checked | N16: Target | Y16: https://streetsoftoronto.com/food/5-spots-on-ossington-every-foodie-needs-to-try/
A17: 16 | B17: 1 | C17: Papi & Rosita | D17: Ossington | E17: Restaurant | F17: Comfort food, tacos, pizza, pasta | G17: 198 Ossington Ave | H17: https://www.papiandrosita.com | J17: 416-519-1109 | L17: Newer sister to Papi Chulo's, still building regulars. | M17: Not checked | N17: Target | X17: Check it's open before visiting: weak online evidence. | Y17: https://www.papiandrosita.com
A18: 17 | B18: 1 | C18: Papi Chulo's | D18: Ossington | E18: Restaurant | F18: Mexican | G18: 121 Ossington Ave | H18: https://www.papichulos.ca | I18: @eatpapichulos | L18: Lively, casual Mexican spot that fits a bring-a-friend offer. | M18: Not checked | N18: Target | X18: Check it's open before visiting: weak online evidence. | Y18: https://www.papichulos.ca
A19: 18 | B19: 1 | C19: Pho Tien Thanh | D19: Ossington | E19: Restaurant | F19: Vietnamese | G19: 57 Ossington Ave | H19: https://photienthanh.com | I19: @photienthanhto | J19: 416-588-6997 | K19: $ | L19: Long-standing pho spot, a budget-friendly anchor. | M19: Not checked | N19: Target | Y19: https://guide.michelin.com/ca/en/ontario/toronto/restaurant/pho-tien-thanh
A20: 19 | B20: 1 | C20: Please & Thank You | D20: Ossington | E20: Restaurant | F20: Global small plates | G20: 108 Ossington Ave | I20: @pandtytoronto | L20: Small plates mostly under $20, from the OddSeoul team. | M20: Not checked | N20: Target | Y20: https://streetsoftoronto.com/food/team-behind-one-of-ossingtons-best-restaurants-just-opened-another-must-visit-spot/
A21: 20 | B21: 1 | C21: Taberna LX | D21: Ossington | E21: Restaurant | F21: Portuguese | G21: 1161 Dundas St W | H21: https://tabernalx.com | I21: @taberna_lx_to | J21: 416-516-6660 | L21: Newer Portuguese room near Ossington and Dundas. | M21: Not checked | N21: Target | Y21: https://foodism.ca/eat-drink/bars-restaurants/best-new-restaurants-toronto-fall-2025/
A22: 21 | B22: 1 | C22: The Haifa Room | D22: Ossington | E22: Restaurant | F22: Israeli, Middle Eastern | G22: 224 Ossington Ave | H22: https://www.thehaifaroom.com | L22: Shareable Israeli plates at Ossington and Dundas, easy to bring a friend. | M22: Not checked | N22: Target | X22: Check it's open before visiting: weak online evidence. | Y22: https://www.thehaifaroom.com
A23: 22 | B23: 1 | C23: The Lunch Lady of Saigon | D23: Ossington | E23: Restaurant | F23: Vietnamese | G23: 93 Ossington Ave | H23: https://thelunchlady.com | J23: 647-748-9550 | K23: $$ | L23: New Bib Gourmand with lunch and dinner service. | M23: Not checked | N23: Target | Y23: https://guide.michelin.com/ca/en/ontario/toronto/restaurant/the-lunch-lady-of-saigon
A24: 23 | B24: 1 | C24: Union | D24: Ossington | E24: Restaurant | F24: French bistro, seasonal | G24: 72 Ossington Ave | H24: https://union72.ca | I24: @union_restaurant | J24: 416-850-0093 | K24: $$$ | L24: Long-running seasonal bistro, a natural fit for a second-main offer. | M24: Not checked | N24: Target | Y24: https://guide.michelin.com/ca/en/ontario/toronto/restaurant/union-1198909
A25: 24 | B25: 1 | C25: The Lakeview | D25: Ossington | E25: Brunch | F25: Diner | G25: 1132 Dundas St W | H25: http://www.thelakeviewrestaurant.ca | I25: @thelakeviewdiner | J25: 416-850-8886 | L25: Classic diner at Ossington and Dundas with all-day breakfast. | M25: Not checked | N25: Target | X25: Check it's open before visiting: weak online evidence. | Y25: http://www.thelakeviewrestaurant.ca
A26: 25 | B26: 1 | C26: I Deal Coffee & Wine | D26: Ossington | E26: Café | F26: Coffee, pastries | G26: 162 Ossington Ave | L26: Early-opening café with a patio, good for weekday mornings. | M26: Not checked | N26: Target | Y26: https://www.designlinesmagazine.com/ossington-strip-neighbourhood-guide/
A27: 26 | B27: 1 | C27: Linny's Luncheonette | D27: Ossington | E27: Café | F27: Deli sandwiches | G27: 174 Ossington Ave | I27: @linnysluncheonette | L27: Daytime deli counter, suits a lunch offer. | M27: Not checked | N27: Target | Y27: https://streetsoftoronto.com/food/restaurants/the-6-best-new-restaurants-on-ossington/
A28: 27 | B28: 1 | C28: Manita | D28: Ossington | E28: Café | F28: All-day café, Mediterranean small plates | G28: 210 Ossington Ave | H28: https://www.manita.ca | I28: @manita.toronto | J28: 416-551-2230 | L28: All-day café that works for brunch and quiet weekday dinners. | M28: Not checked | N28: Target | X28: Check it's open before visiting: weak online evidence. | Y28: https://www.manita.ca
A29: 28 | B29: 1 | C29: Misc Coffee | D29: Ossington | E29: Café | F29: Coffee | G29: 299 Ossington Ave | L29: New café at the north end of the strip. | M29: Not checked | N29: Target | Y29: https://foodism.ca/eat-drink/bars-restaurants/best-new-restaurants-toronto-fall-2025/
A30: 29 | B30: 1 | C30: Stefano's Diner | D30: Ossington | E30: Café | F30: Vegan Italian sandwiches | G30: 1265 Dundas St W | H30: https://stefanosdiner.com | I30: @stefanosdiner | J30: 437-318-8697 | L30: Casual plant-based diner, sister to Gia. | M30: Not checked | N30: Target | Y30: https://streetsoftoronto.com/food/5-restaurants-on-dundas-west-that-every-foodie-needs-to-try/
A31: 30 | B31: 1 | C31: Formula Fig (Ossington) | D31: Ossington | E31: Spa | F31: Facial studio | G31: 50 Ossington Ave | H31: https://formulafig.com/ | I31: @formulafig | L31: Free targeted add-on with a signature facial. | M31: Not checked | N31: Target | Y31: https://curiocity.com/toronto-spas-massages-facials/
A32: 31 | B32: 1 | C32: Academy of Lions | D32: Ossington | E32: Studio | F32: Functional fitness | G32: 1083 Dundas St W | H32: https://www.academyoflions.com/ | I32: @academyoflions | L32: Bring a friend to a group class free. | M32: Not checked | N32: Target | Y32: https://www.academyoflions.com/
A33: 32 | B33: 1 | C33: Assembly Movement | D33: Ossington | E33: Studio | F33: Reformer pilates | G33: 832 College St; 1114 Queen St E | H33: https://www.assemblymovement.ca/ | I33: @assembly_movement | L33: Bring a friend to a reformer class free. | M33: Not checked | N33: Target | Y33: https://www.assemblymovement.ca/
A34: 33 | B34: 1 | C34: Downward Dog Yoga | D34: Ossington | E34: Studio | F34: Yoga (vinyasa, strength, pilates) | G34: 30 Ossington Ave, 2nd floor | H34: https://downwarddog.com/ | I34: @downwarddogyoga | L34: Bring a friend to class free. | M34: Not checked | N34: Target | Y34: https://ma.to/venue/downwarddogyoga
A35: 34 | B35: 1 | C35: MuseMovement | D35: Ossington | E35: Studio | F35: Pilates, barre and yoga | G35: 180 Shaw St, #204 | H35: https://www.musemovement.ca/ | I35: @muse_movement | L35: Bring a friend to a mat or barre class free. | M35: Not checked | N35: Target | Y35: https://www.musemovement.ca/
A36: 35 | B36: 1 | C36: Octopus Garden Yoga | D36: Ossington | E36: Studio | F36: Yoga and holistic centre | G36: 967 College St | H36: https://octopusgardenyoga.com/ | L36: Bring a friend to a drop-in class free. | M36: Not checked | N36: Target | X36: Check it's open before visiting: weak online evidence. | Y36: https://www.blogto.com/fitness/octopus-garden-yoga-toronto/
A37: 36 | B37: 1 | C37: Ride Cycle Club Ossington | D37: Ossington | E37: Studio | F37: Indoor cycling | G37: 19 Ossington Ave | H37: https://ridecycleclub.com/ | I37: @ridecycleclub | L37: Bring a friend to a ride free. | M37: Not checked | N37: Target | Y37: https://ridecycleclub.com/
A38: 37 | B38: 1 | C38: YogaSpace | D38: Ossington | E38: Studio | F38: Yoga | G38: 699 College St | H38: https://www.yogaspace.net/ | I38: @yogaspaceto | J38: 416-530-1622 | L38: Bring a friend to class free. | M38: Not checked | N38: Target | Y38: https://www.yogaspace.net/contact
A39: 38 | B39: 1 | C39: 156 OneFiveSix | D39: Queen West | E39: Restaurant | F39: Korean with French technique | G39: 1100 Queen St W | H39: https://156onefivesix.com | I39: @onefivesix_156 | J39: 416-469-4150 | K39: $$$ | L39: Michelin-listed Korean dinner spot, open Tuesday to Sunday. | M39: Not checked | N39: Target | Y39: https://guide.michelin.com/ca/en/ontario/toronto/restaurant/156-onefivesix
A40: 39 | B40: 1 | C40: Aleria | D40: Queen West | E40: Restaurant | F40: Greek | G40: 1070 Queen St W | H40: https://www.aleria.ca | I40: @aleria1070 | J40: 416-519-1109 | L40: Greek dining room with space for private dining. | M40: Not checked | N40: Target | X40: Check it's open before visiting: weak online evidence. | Y40: https://www.aleria.ca
...

Sheet Lists
A1: Status | B1: Neighbourhood | C1: Category | D1: How we know them | E1: Open?
A2: Target | B2: Ossington | C2: Restaurant | D2: Walked in | E2: Not checked
A3: Contacted | B3: Queen West | C3: Brunch | D3: Email | E3: Confirmed open
A4: Meeting booked | B4: King West | C4: Café | D4: Instagram | E4: Closed
A5: Met | B5: Financial District | C5: Bakery | D5: Friend
A6: LOI signed | B6: Yorkville | C6: Spa | D6: Referral
A7: Agreement signed | B7: Leslieville | C7: Studio | D7: Event
A8: Not now | B8: Little Italy | C8: Hotel restaurant or spa
B9: Kensington and Chinatown | C9: Experience
B10: The Annex
B11: Roncesvalles
B12: Danforth
B13: Liberty Village
B14: Little Portugal
B15: Parkdale
B16: The Junction
B17: St. Clair West
B18: Distillery and Corktown
B19: Summerhill and Rosedale
B20: Midtown
B21: Leaside
B22: Riverdale
